Workbook

Sheet Catalogo
A1: ID | B1: Tipo | C1: SKU | D1: Nombre | E1: Publicado | F1: ¿Está destacado? | G1: Visibilidad en el catálogo | H1: Descripción corta | I1: Descripción | J1: Día en que empieza el precio rebajado | K1: Día en que termina el precio rebajado | L1: Estado del impuesto | M1: Clase de impuesto | N1: ¿En inventario? | O1: Inventario | P1: Cantidad de bajo inventario | Q1: ¿Permitir reservas de productos agotados? | R1: ¿Vendido individualmente? | S1: Peso (kg) | T1: Longitud (cm) | U1: Anchura (cm) | V1: Altura (cm) | W1: ¿Permitir valoraciones de clientes? | X1: Nota de compra | Y1: Precio rebajado | Z1: Precio normal | AA1: Categorías | AB1: Etiquetas | AC1: Clase de envío | AD1: Imágenes | AE1: Límite de descargas | AF1: Días de caducidad de la descarga | AG1: Superior | AH1: Productos agrupados | AI1: Ventas dirigidas | AJ1: Ventas cruzadas | AK1: URL externa | AL1: Texto del botón | AM1: Posición | AN1: Nombre del atributo 1 | AO1: Valor(es) del atributo 1 | AP1: Atributo visible 1 | AQ1: Atributo global 1 | AR1: Nombre de la descarga 1 | AS1: URL de la descarga 1
B2: simple | D2: Hoddie F&T | E2: 1 | F2: 0 | G2: visible | H2: Excelente hoddie para el frio | L2: taxable | M2: parent | N2: 1 | Q2: 0 | R2: 0 | W2: 1 | Z2: 750 | AA2: Hoddies | AD2: https://dominio.com/wp-content/uploads/2021/07/hoddie-1.jpg, https://dominio.com/wp-content/uploads/2021/07/hoddie-2.jpg, https://dominio.com/wp-content/uploads/2021/07/hoddie-3.jpg | AM2: 0

Sheet CATALOGO PAGINA
A1: ID | B1: Type | C1: SKU | D1: Name | E1: Published | F1: Is featured? | G1: Visibility in catalog | H1: Short description | I1: Description | J1: Date sale price starts | K1: Date sale price ends | L1: Tax status | M1: Tax class | N1: In stock? | O1: Stock | P1: Low stock amount | Q1: Backorders allowed? | R1: Sold individually? | S1: Weight (kg) | T1: Length (cm) | U1: Width (cm) | V1: Height (cm) | W1: Allow customer reviews? | X1: Purchase note | Y1: Sale price | Z1: Regular price | AA1: Categories | AB1: Images | AC1: Meta: _product_location | AD1: Meta: _items_per_products | AE1: Meta: product_step | AF1: Meta: _wpd_ai_product_cost | AG1: % de descuento
B2: simple | C2: FD853 | D2: Tall wall sanitizing shoe & Boot Mat - FD853 | E2: 0 | F2: 0 | G2: hidden | H2: Tall wall sanitizing shoe & Boot Mat | I2: Sanitizing mat | N2: 0 | O2: 0 | Z2: 2.99 | AA2: Mats | AB2: https://fantasydiscountwholesale.com/wp-content/uploads/2023/10/FD853.jpeg | AC2: 1 | AD2: 6 | AE2: =AD2 -> 6 | AF2: 3.41 | AG2: =AF2*-0.707+AF2 -> 0.99913 | AH2: =Z2*0.1-Z2 -> -2.691 | AI2: =AF2*0.05+AF2 -> 3.5805 | AJ2: =1-AF2/Z2 -> -0.14046823
B3: simple | C3: FD1013S | D3: TOTUMAS PEQUENA / GUIRA SMALL - FD1013S | E3: 1 | F3: 0 | G3: visible | H3: These small totumas are natural dried fruits carved by hand | I3: A compact and traditional percussion instrument handcrafted from a small gourd. With its unique shape and sound, this guira adds a distinctive rhythmic element to your music. | N3: 1 | O3: 1000 | Z3: 0.85 | AA3: Miscellaneous | AB3: https://fantasydiscountwholesale.com/wp-content/uploads/2023/10/FD1013S.jpeg | AC3: 1 | AD3: 12 | AE3: =AD3 -> 12 | AF3: 0.29 | AG3: =AF3*1.6+AF3 -> 0.754 | AH3: =Z3*0.1-Z3 -> -0.765 | AI3: =AF3*0.4+AF3 -> 0.406 | AJ3: =1-AF3/Z3 -> 0.65882353
B4: simple | C4: FD1013M | D4: TOTUMAS MEDIANA / GUIRA MEDIUM - FD1013M | E4: 1 | F4: 0 | G4: visible | H4: TOTUMAS MEDIANA / GUIRA MEDIUM - FD1013M | I4: Totumas Mediana / Guira Medium – FD1013M is a versatile, durable bowl ideal for serving soups, stews, or traditional dishes. Perfect for restaurants, markets, and wholesale distribution. Lightweight and reusable. | N4: 1 | O4: 1000 | Z4: 1.5 | AA4: Miscellaneous | AB4: https://fantasydiscountwholesale.com/wp-content/uploads/2023/10/FD1013M.jpeg | AC4: 1 | AD4: 12 | AE4: =AD4 -> 12 | AF4: 0.29 | AG4: =AF4*3.3+AF4 -> 1.247 | AH4: =Z4*0.1-Z4 -> -1.35 | AI4: =AF4*0.4+AF4 -> 0.406 | AJ4: =1-AF4/Z4 -> 0.80666667
B5: simple | C5: FD1013L | D5: TOTUMAS GRANDE / GUIRA LARGE - FD1013L | E5: 1 | F5: 0 | G5: visible | H5: TOTUMAS GRANDE / GUIRA LARGE - FD1013L | I5: These large guira instruments are crafted from sizable gourds, offering a rich and distinctive percussion sound. Handmade with care, they are perfect for musicians looking to add an authentic and captivating element to their music. | N5: 1 | O5: 1000 | Z5: 2 | AA5: Miscellaneous | AB5: https://fantasydiscountwholesale.com/wp-content/uploads/2023/10/FD1013L.jpeg | AC5: 1 | AD5: 12 | AE5: =AD5 -> 12 | AF5: 0.29 | AG5: =AF5*5.02+AF5 -> 1.7458 | AH5: =Z5*0.1-Z5 -> -1.8 | AI5: =AF5*0.4+AF5 -> 0.406 | AJ5: =1-AF5/Z5 -> 0.855
B6: simple | C6: CN91092-A | D6: Orange Oven Cleaner Heavy Duty 12OZ - CN91092-A | E6: 0 | F6: 0 | G6: hidden | H6: Orange Oven Cleaner Heavy Duty 12OZ - CN91092-A | I6: Orange Oven Cleaner Heavy Duty 12oz (CN91092-A) delivers powerful grease-cutting action for tough, baked-on messes. Its citrus formula cleans ovens, grills, and stovetops effectively. Ideal for retail, household use, and wholesale or discount stores. | N6: 0 | O6: 0 | Z6: 1.49 | AA6: cleaning supplies | AB6: https://fantasydiscountwholesale.com/wp-content/uploads/2025/06/CN91092-A.jpg | AC6: 1 | AD6: 12 | AE6: =AD6 -> 12 | AF6: 0.99 | AG6: =AF6*0.4+AF6 -> 1.386 | AH6: =Z6*0.1-Z6 -> -1.341 | AI6: =AF6*0.4+AF6 -> 1.386 | AJ6: =1-AF6/Z6 -> 0.33557047
B7: simple | C7: 41661 | D7: Roma Liquid Detergent 33.8OZ - 41661 | E7: 0 | F7: 0 | G7: hidden | H7: Roma Liquid Detergent 33.8OZ - 41661 | I7: Roma Liquid Detergent 33.8oz (41661) offers powerful cleaning for all types of laundry, removing tough stains while being gentle on fabrics. Leaves clothes fresh and bright. Ideal for retail, household use, and wholesale or discount stores. | N7: 0 | O7: 0 | Z7: 3.07 | AA7: cleaning supplies | AB7: https://fantasydiscountwholesale.com/wp-content/uploads/2025/06/41661.jpg | AC7: 1 | AD7: 6 | AE7: =AD7 -> 6 | AF7: 2.05 | AG7: =AF7*0.4+AF7 -> 2.87 | AH7: =Z7*0.1-Z7 -> -2.763 | AI7: =AF7*0.4+AF7 -> 2.87 | AJ7: =1-AF7/Z7 -> 0.33224756
B8: simple | C8: FD1606 | D8: Entrance door mat - FD1606 | E8: 1 | F8: 0 | G8: visible | H8: Entrance door mat- Chef 45*70 cm | I8: Charming entrance door mat featuring a chef design, measuring 45x70 cm. Perfect for kitchens or entryways, this mat traps dirt and moisture. Made with durable materials and a non-slip backing for added safety. Easy to clean and maintain, enhancing any home's decor. | N8: 1 | O8: 1000 | Z8: 3.5 | AA8: Mats | AB8: https://fantasydiscountwholesale.com/wp-content/uploads/2023/10/FD1606.jpeg | AC8: 1-1 | AD8: 12 | AE8: =AD8 -> 12 | AF8: 1.4 | AG8: =AF8*1+AF8 -> 2.8 | AH8: =Z8*0.1-Z8 -> -3.15 | AI8: =AF8*0.4+AF8 -> 1.96 | AJ8: =1-AF8/Z8 -> 0.6
B9: simple | C9: 801440 | D9: COB LED Light Switch (Magnetic Back) Cordless - 801440 | E9: 1 | F9: 0 | G9: visible | H9: COB LED Light Switch (Magnetic Back) Cordless | I9: Installs virtually anywhere, portable magnet mounts on the back, No electrician Needed | N9: 1 | O9: 1000 | Z9: 1.5 | AA9: Miscellaneous | AB9: https://fantasydiscountwholesale.com/wp-content/uploads/2023/10/801440-1.jpeg | AC9: 1-1 | AD9: 12 | AE9: =AD9 -> 12 | AF9: 0.98 | AG9: =AF9*0.4+AF9 -> 1.372 | AH9: =Z9*0.1-Z9 -> -1.35 | AI9: =AF9*0.4+AF9 -> 1.372 | AJ9: =1-AF9/Z9 -> 0.34666667
B10: simple | C10: 8888 | D10: scruber salvauñas - 8888 SA-64 | E10: 1 | F10: 0 | G10: visible | H10: Esponja Salvauña - SA-64 | I10: Esponja Salvaluna – SA‑64: Dual-use cleaning sponge designed to protect nails while scrubbing. Combines a soft cellulose side with a gentle abrasive surface. Ideal for wholesale to cleaning and kitchen goods retailers. | N10: 1 | O10: 1000 | Z10: 0.5 | AA10: cleaning supplies | AB10: https://fantasydiscountwholesale.com/wp-content/uploads/2025/06/8888.jpg | AC10: 1-1 | AD10: 48 | AE10: =AD10 -> 48 | AF10: 0.36 | AG10: =AF10*0.3+AF10 -> 0.468 | AH10: =Z10*0.1-Z10 -> -0.45 | AI10: =AF10*0.4+AF10 -> 0.504 | AJ10: =1-AF10/Z10 -> 0.28
B11: simple | C11: 6134 | D11: SAPOLIO LIME CLEANER (SACASARRO) 12/500ML sa-43 - 6134 | E11: 1 | F11: 0 | G11: visible | H11: SAPOLIO LIME CLEANER (SACASARRO) 12/500ML - 6134 | I11: Softsoap Aquarium Series combines enchanting designs from the sea with Antibacterial liquid soap. It contains germ fighting ingredient to provide strong antibacterial protection. Like other Softsoap products, Softsoap Aquarium Series liquid soap contains light moisturizers to help leave your hands clean and soft. | N11: 1 | O11: 1000 | Z11: 1.75 | AA11: cleaning supplies | AB11: https://fantasydiscountwholesale.com/wp-content/uploads/2023/10/6134.jpeg | AC11: 1-2 | AD11: 12 | AE11: =AD11 -> 12 | AF11: 1.34 | AG11: =AF11*0.25+AF11 -> 1.675 | AH11: =Z11*0.1-Z11 -> -1.575 | AI11: =AF11*0.4+AF11 -> 1.876 | AJ11: =1-AF11/Z11 -> 0.23428571
B12: simple | C12: 8594 | D12: SAPOLIO CLEAM CLEANER SOFTSCRUB sa-44 - 8594 | E12: 1 | F12: 0 | G12: visible | H12: SAPOLIO CLEAM CLEANER SOFTSCRUB - 8594 | I12: Softsoap Aquarium Series combines enchanting designs from the sea with Antibacterial liquid soap. It contains germ fighting ingredient to provide strong antibacterial protection. Like other Softsoap products, Softsoap Aquarium Series liquid soap contains light moisturizers to help leave your hands clean and soft. | N12: 1 | O12: 1000 | Z12: 2.35 | AA12: cleaning supplies | AB12: https://fantasydiscountwholesale.com/wp-content/uploads/2023/10/8594-1.jpeg | AC12: 1-2 | AD12: 12 | AE12: =AD12 -> 12 | AF12: 1.79 | AG12: =AF12*0.25+AF12 -> 2.2375 | AH12: =Z12*0.1-Z12 -> -2.115 | AI12: =AF12*0.3+AF12 -> 2.327 | AJ12: =1-AF12/Z12 -> 0.23829787
B13: simple | C13: 7532 | D13: Sapolio POWDER CLEANER Multi purpose sa-45 - 7532 12/450ML | E13: 1 | F13: 0 | G13: visible | H13: Sapolio POWDER CLEANER Multi purpose - 7532 12/450ML | I13: Energizing Hair Styling Gel for Extreme Long Lasting Hold, Gorilla Snot Gel is Ultimate Hair Gel to Energize any Hairstyle | N13: 1 | O13: 1000 | Z13: 1.39 | AA13: cleaning supplies | AB13: https://fantasydiscountwholesale.com/wp-content/uploads/2023/10/7532.jpeg | AC13: 1-2 | AD13: 12 | AE13: =AD13 -> 12 | AF13: 1.04 | AG13: =AF13*0.25+AF13 -> 1.3 | AH13: =Z13*0.1-Z13 -> -1.251 | AI13: =AF13*0.3+AF13 -> 1.352 | AJ13: =1-AF13/Z13 -> 0.25179856
B14: simple | C14: 9300 | D14: Sapolio 650 ml limpia vidrios lavanda sa-41 - 9300 | E14: 1 | F14: 0 | G14: visible | H14: Sapolio 650 ml limpia vidrios lavanda | I14: Sapolio Glass Cleaner Lavender (650ml) delivers a streak-free shine while leaving a pleasant lavender scent. Its powerful formula removes dust, fingerprints, and smudges with ease. Perfect for windows, mirrors, and glass surfaces. Ideal for wholesale and discount stores. | N14: 1 | O14: 1000 | Z14: 1.75 | AA14: cleaning supplies | AB14: https://fantasydiscountwholesale.com/wp-content/uploads/2025/02/9300.jpeg | AC14: 1-2 | AD14: 12 | AE14: =AD14 -> 12 | AF14: 1.35 | AG14: =AF14*0.25+AF14 -> 1.6875 | AH14: =Z14*0.1-Z14 -> -1.575 | AI14: =AF14*0.3+AF14 -> 1.755 | AJ14: =1-AF14/Z14 -> 0.22857143
B15: simple | C15: 7348 | D15: Sapolio Dish Liquid Lemon 17 Oz sa-34 - 7348 | E15: 1 | F15: 0 | G15: visible | H15: Sapolio Dish Liquid Lemon 17 Oz - 7348 | I15: Energizing Hair Styling Gel for Extreme Long Lasting Hold, Gorilla Snot Gel is Ultimate Hair Gel to Energize any Hairstyle | N15: 1 | O15: 1000 | Z15: 1.39 | AA15: cleaning supplies | AB15: https://fantasydiscountwholesale.com/wp-content/uploads/2023/10/7348.jpeg | AC15: 1-3 | AD15: 12 | AE15: =AD15 -> 12 | AF15: 1.04 | AG15: =AF15*0.25+AF15 -> 1.3 | AH15: =Z15*0.1-Z15 -> -1.251 | AI15: =AF15*0.3+AF15 -> 1.352 | AJ15: =1-AF15/Z15 -> 0.25179856
B16: simple | C16: 7355 | D16: Sapolio liquid Dish Soap Apple sa-35 - 7355 | E16: 1 | F16: 0 | G16: visible | H16: Sapolio liquid Dish Soap Apple - 7355 | I16: Energizing Hair Styling Gel for Extreme Long Lasting Hold, Gorilla Snot Gel is Ultimate Hair Gel to Energize any Hairstyle | N16: 1 | O16: 1000 | Z16: 1.39 | AA16: cleaning supplies | AB16: https://fantasydiscountwholesale.com/wp-content/uploads/2023/10/7355-1.jpeg | AC16: 1-3 | AD16: 12 | AE16: =AD16 -> 12 | AF16: 1.04 | AG16: =AF16*0.25+AF16 -> 1.3 | AH16: =Z16*0.1-Z16 -> -1.251 | AI16: =AF16*0.3+AF16 -> 1.352 | AJ16: =1-AF16/Z16 -> 0.25179856
B17: simple | C17: 0361 | D17: Aval jabon lavanda sa-27 400ml - 0361 | E17: 1 | F17: 0 | G17: visible | H17: Aval jabon lavanda 400ml | I17: Aval Rosas Liquid Soap (400ml) offers a gentle yet effective cleanse with a pleasant rose fragrance. Its moisturizing formula leaves hands soft and refreshed. Ideal for daily use in homes or businesses. Great for wholesale and discount stores. | N17: 1 | O17: 1000 | Z17: 1.45 | AA17: Beauty & Personal Care | AB17: https://fantasydiscountwholesale.com/wp-content/uploads/2025/02/8891.jpeg | AC17: 1-3 | AD17: 12 | AE17: =AD17 -> 12 | AF17: 1.09 | AG17: =AF17*0.3+AF17 -> 1.417 | AH17: =Z17*0.1-Z17 -> -1.305 | AI17: =AF17*0.3+AF17 -> 1.417 | AJ17: =1-AF17/Z17 -> 0.24827586
B18: simple | C18: 8914 | D18: Aval jabon rosas sa-28 400ml - 8914 | E18: 1 | F18: 0 | G18: visible | H18: Aval jabon rosas 400ml | I18: Aval Rosas Liquid Soap (400ml) provides a deep yet gentle cleanse with a delightful rose scent. Its moisturizing formula keeps hands soft and fresh. Perfect for everyday use in homes or businesses. Ideal for wholesale and discount stores. | N18: 1 | O18: 1000 | Z18: 1.45 | AA18: Beauty & Personal Care | AB18: https://fantasydiscountwholesale.com/wp-content/uploads/2025/02/8914.jpeg | AC18: 1-3 | AD18: 12 | AE18: =AD18 -> 12 | AF18: 1.09 | AG18: =AF18*0.3+AF18 -> 1.417 | AH18: =Z18*0.1-Z18 -> -1.305 | AI18: =AF18*0.4+AF18 -> 1.526 | AJ18: =1-AF18/Z18 -> 0.24827586
B19: simple | C19: 3543 | D19: Lavavajilla pasta naranja 360g - 3543 - sa-33 | E19: 1 | F19: 0 | G19: visible | H19: Lavavajilla pasta naranja 360g | I19: Orange-Scented Dishwashing Paste (360g) cuts through grease and tough stains with ease. Its concentrated formula ensures long-lasting use, leaving dishes sparkling clean with a fresh citrus scent. Ideal for households and businesses. Perfect for wholesale and discount stores. | N19: 1 | O19: 1000 | Z19: 1.59 | AA19: cleaning supplies | AB19: https://fantasydiscountwholesale.com/wp-content/uploads/2025/02/3543.jpeg | AC19: 1-3 | AD19: 12 | AE19: =AD19 -> 12 | AF19: 1.16 | AG19: =AF19*0.25+AF19 -> 1.45 | AH19: =Z19*0.1-Z19 -> -1.431 | AI19: =AF19*0.3+AF19 -> 1.508 | AJ19: =1-AF19/Z19 -> 0.27044025
B20: simple | C20: 7729 | D20: Lavavajilla pasta limon 330g - 7729 - sa-30 | E20: 1 | F20: 0 | G20: visible | H20: Lavavajilla pasta limon 330g | I20: Lemon-Scented Dishwashing Paste (330g) effectively removes grease and tough stains while leaving a refreshing citrus scent. Its concentrated formula ensures long-lasting use and sparkling clean dishes. Ideal for households and businesses. Perfect for wholesale and discount stores. | N20: 1 | O20: 1000 | Z20: 1.39 | AA20: cleaning supplies | AB20: https://fantasydiscountwholesale.com/wp-content/uploads/2025/02/7729.jpeg | AC20: 1-3 | AD20: 12 | AE20: =AD20 -> 12 | AF20: 1.04 | AG20: 1.3 | AH20: =Z20*0.1-Z20 -> -1.251 | AI20: =AF20*0.4+AF20 -> 1.456 | AJ20: =1-AF20/Z20 -> 0.25179856
B21: simple | C21: 6026 | D21: Sapolio Air freshner Anti-tabacco sa-17 - 6026 | E21: 1 | F21: 0 | G21: visible | H21: Sapolio Air freshner Anti-tabacco - 6026 | I21: Energizing Hair Styling Gel for Extreme Long Lasting Hold, Gorilla Snot Gel is Ultimate Hair Gel to Energize any Hairstyle | N21: 1 | O21: 1000 | Z21: 1.9 | AA21: Air Freshener | AB21: https://fantasydiscountwholesale.com/wp-content/uploads/2023/10/6026.jpeg | AC21: 1-4 | AD21: 12 | AE21: =AD21 -> 12 | AF21: 1.46 | AG21: =AF21*0.25+AF21 -> 1.825 | AH21: =Z21*0.1-Z21 -> -1.71 | AI21: =AF21*0.4+AF21 -> 2.044 | AJ21: =1-AF21/Z21 -> 0.23157895
B22: simple | C22: 8208 | D22: SAPOLIO 550 ML . STAIN REMOVER ROPA COLOR sa-08 - 8208 | E22: 1 | F22: 0 | G22: visible | H22: SAPOLIO STAIN REMOVER ROPA COLOR 550ML - 8208 | I22: Energizing Hair Styling Gel for Extreme Long Lasting Hold, Gorilla Snot Gel is Ultimate Hair Gel to Energize any Hairstyle | N22: 1 | O22: 1000 | Z22: 1.39 | AA22: cleaning supplies | AB22: https://fantasydiscountwholesale.com/wp-content/uploads/2023/10/8208.jpeg | AC22: 1-4 | AD22: 12 | AE22: =AD22 -> 12 | AF22: 1.05 | AG22: =AF22*0.28+AF22 -> 1.344 | AH22: =Z22*0.1-Z22 -> -1.251 | AI22: =AF22*0.4+AF22 -> 1.47 | AJ22: =1-AF22/Z22 -> 0.24460432
B23: simple | C23: 7712 | D23: Lavavajilla pasta limon 200g sa-32 - 7712 | E23: 1 | F23: 0 | G23: visible | H23: Lavavajilla pasta limon 200g | I23: Lemon-Scented Dishwashing Paste (200g) powerfully cuts through grease and tough stains, leaving dishes spotless with a fresh citrus scent. Its concentrated formula ensures long-lasting use. Ideal for households and businesses. Perfect for wholesale and discount stores. | N23: 1 | O23: 1000 | Z23: 0.75 | AA23: cleaning supplies | AB23: https://fantasydiscountwholesale.com/wp-content/uploads/2025/02/7712.jpeg | AC23: 1-4 | AD23: 24 | AE23: =AD23 -> 24 | AF23: 0.58 | AG23: =AF23*0.25+AF23 -> 0.725 | AH23: =Z23*0.1-Z23 -> -0.675 | AI23: =AF23*0.4+AF23 -> 0.812 | AJ23: =1-AF23/Z23 -> 0.22666667
B24: simple | C24: 6088 | D24: Sapolio air freshner Bebe Arrullo - 6088 SA-25 | E24: 1 | F24: 0 | G24: visible | H24: Sapolio air freshner Bebe Arrullo - 6088 SA-25 | I24: Sapolio Baby Lullaby Air Freshener – SA‑25: gentle-scent spray neutralizes odors and fills rooms with a soft, comforting baby powder fragrance. Ideal for bulk wholesale to retailers, nurseries, and hospitality. | N24: 1 | O24: 1000 | Z24: 1.9 | AA24: Air Freshener | AB24: https://fantasydiscountwholesale.com/wp-content/uploads/2025/06/6088.jpg | AC24: 1-4 | AD24: 12 | AE24: =AD24 -> 12 | AF24: 1.46 | AG24: =AF24*0.25+AF24 -> 1.825 | AH24: =Z24*0.1-Z24 -> -1.71 | AI24: =AF24*0.4+AF24 -> 2.044 | AJ24: =1-AF24/Z24 -> 0.23157895
B25: simple | C25: 5218 | D25: Sapolio Air freshner Apple Cinnamon sa-20 - 5218 | E25: 1 | F25: 0 | G25: visible | H25: Sapolio Air freshner Apple Cinnamon - 5218 | I25: Softsoap Aquarium Series combines enchanting designs from the sea with Antibacterial liquid soap. It contains germ fighting ingredient to provide strong antibacterial protection. Like other Softsoap products, Softsoap Aquarium Series liquid soap contains light moisturizers to help leave your hands clean and soft. | N25: 1 | O25: 1000 | Z25: 1.9 | AA25: Air Freshener | AB25: https://fantasydiscountwholesale.com/wp-content/uploads/2023/10/5218.jpeg | AC25: 1-5 | AD25: 12 | AE25: =AD25 -> 12 | AF25: 1.46 | AG25: =AF25*0.25+AF25 -> 1.825 | AH25: =Z25*0.1-Z25 -> -1.71 | AI25: =AF25*0.4+AF25 -> 2.044 | AJ25: =1-AF25/Z25 -> 0.23157895
B26: simple | C26: 5999 | D26: Sapolio Air freshner Potpourri sa-18 - 5999 | E26: 1 | F26: 0 | G26: visible | H26: Sapolio Air freshner Potpourri - 5999 | I26: Softsoap Aquarium Series combines enchanting designs from the sea with Antibacterial liquid soap. It contains germ fighting ingredient to provide strong antibacterial protection. Like other Softsoap products, Softsoap Aquarium Series liquid soap contains light moisturizers to help leave your hands clean and soft. | N26: 1 | O26: 1000 | Z26: 1.9 | AA26: Air Freshener | AB26: https://fantasydiscountwholesale.com/wp-content/uploads/2023/10/5999.jpeg | AC26: 1-5 | AD26: 12 | AE26: =AD26 -> 12 | AF26: 1.46 | AG26: =AF26*0.25+AF26 -> 1.825 | AH26: =Z26*0.1-Z26 -> -1.71 | AI26: =AF26*0.4+AF26 -> 2.044 | AJ26: =1-AF26/Z26 -> 0.23157895
B27: simple | C27: 9637 | D27: Perfumatic Sapolio Refill French Vanilla - 9637 | E27: 0 | F27: 0 | G27: hidden | H27: Perfumatic Sapolio Refill French Vanilla - 9637 | I27: Softsoap Aquarium Series combines enchanting designs from the sea with Antibacterial liquid soap. It contains germ fighting ingredient to provide strong antibacterial protection. Like other Softsoap products, Softsoap Aquarium Series liquid soap contains light moisturizers to help leave your hands clean and soft. | N27: 0 | O27: 0 | Z27: 2.29 | AA27: Air Freshener | AB27: https://fantasydiscountwholesale.com/wp-content/uploads/2023/10/9637.jpeg | AC27: 1-5 | AD27: 12 | AE27: =AD27 -> 12 | AF27: 1.82 | AG27: =AF27*0.25+AF27 -> 2.275 | AH27: =Z27*0.1-Z27 -> -2.061 | AI27: =AF27*0.4+AF27 -> 2.548 | AJ27: =1-AF27/Z27 -> 0.20524017
B28: simple | C28: 5982 | D28: Sapolio Air freshner Lavander sa-23 - 5982 | E28: 1 | F28: 0 | G28: visible | H28: Sapolio Air freshner Lavander - 5982 | I28: Energizing Hair Styling Gel for Extreme Long Lasting Hold, Gorilla Snot Gel is Ultimate Hair Gel to Energize any Hairstyle | N28: 1 | O28: 1000 | Z28: 1.9 | AA28: Air Freshener | AB28: https://fantasydiscountwholesale.com/wp-content/uploads/2023/10/5982.jpeg | AC28: 1-5 | AD28: 12 | AE28: =AD28 -> 12 | AF28: 1.46 | AG28: =AF28*0.25+AF28 -> 1.825 | AH28: =Z28*0.1-Z28 -> -1.71 | AI28: =AF28*0.4+AF28 -> 2.044 | AJ28: =1-AF28/Z28 -> 0.23157895
B29: simple | C29: 6853 | D29: Sapolio Air freshner Melon sa-24 - 6853 | E29: 1 | F29: 0 | G29: visible | H29: Sapolio Air freshner Melon - 6853 | I29: Energizing Hair Styling Gel for Extreme Long Lasting Hold, Gorilla Snot Gel is Ultimate Hair Gel to Energize any Hairstyle | N29: 1 | O29: 1000 | Z29: 1.9 | AA29: Air Freshener | AB29: https://fantasydiscountwholesale.com/wp-content/uploads/2023/10/6853.jpeg | AC29: 1-5 | AD29: 12 | AE29: =AD29 -> 12 | AF29: 1.46 | AG29: =AF29*0.25+AF29 -> 1.825 | AH29: =Z29*0.1-Z29 -> -1.71 | AI29: =AF29*0.4+AF29 -> 2.044 | AJ29: =1-AF29/Z29 -> 0.23157895
B30: simple | C30: 6002 | D30: Sapolio Air freshner Rose sa-19 - 6002 | E30: 1 | F30: 0 | G30: visible | H30: Sapolio Air freshner Rose - 6002 | I30: Energizing Hair Styling Gel for Extreme Long Lasting Hold, Gorilla Snot Gel is Ultimate Hair Gel to Energize any Hairstyle | N30: 1 | O30: 1000 | Z30: 1.9 | AA30: Air Freshener | AB30: https://fantasydiscountwholesale.com/wp-content/uploads/2023/10/6002.jpeg | AC30: 1-5 | AD30: 12 | AE30: =AD30 -> 12 | AF30: 1.46 | AG30: =AF30*0.25+AF30 -> 1.825 | AH30: =Z30*0.1-Z30 -> -1.71 | AI30: =AF30*0.4+AF30 -> 2.044 | AJ30: =1-AF30/Z30 -> 0.23157895
B31: simple | C31: 3260 | D31: Sapolio Air freshner Vanilla sa-22 - 3260 | E31: 1 | F31: 0 | G31: visible | H31: Sapolio Air freshner Vanilla - 3260 | I31: Energizing Hair Styling Gel for Extreme Long Lasting Hold, Gorilla Snot Gel is Ultimate Hair Gel to Energize any Hairstyle | N31: 1 | O31: 1000 | Z31: 1.9 | AA31: Air Freshener | AB31: https://fantasydiscountwholesale.com/wp-content/uploads/2023/10/3260.jpeg | AC31: 1-5 | AD31: 12 | AE31: =AD31 -> 12 | AF31: 1.46 | AG31: =AF31*0.25+AF31 -> 1.825 | AH31: =Z31*0.1-Z31 -> -1.71 | AI31: =AF31*0.4+AF31 -> 2.044 | AJ31: =1-AF31/Z31 -> 0.23157895
B32: simple | C32: N-211 | D32: NAIL CLIPPER STAINLESS STEEL - N-211 | E32: 1 | F32: 0 | G32: visible | H32: Stainless Steel Nail Clippers | I32: Finger nail clipper and toe nail clipper - MANICURE - PEDICURE - GROOMING – NAIL CARE | N32: 1 | O32: 1000 | Z32: 5.5 | AA32: Miscellaneous | AB32: https://fantasydiscountwholesale.com/wp-content/uploads/2023/10/211-Corta-unas.jpeg | AC32: 1-6 | AD32: 1 | AE32: =AD32 -> 1 | AF32: 1.56 | AG32: =AF32*1.85+AF32 -> 4.446 | AH32: =Z32*0.1-Z32 -> -4.95 | AI32: =AF32*0.4+AF32 -> 2.184 | AJ32: =1-AF32/Z32 -> 0.71636364
B33: simple | C33: 9113 | D33: Sapolio 1800 ML. stain remover color clothes 60 oz - 9113 - sa-10 | E33: 1 | F33: 0 | G33: visible | H33: Stain remover color clothes 60 oz - 9113 | I33: Energizing Hair Styling Gel for Extreme Long Lasting Hold, Gorilla Snot Gel is Ultimate Hair Gel to Energize any Hairstyle | N33: 1 | O33: 1000 | Z33: 3.89 | AA33: cleaning supplies | AB33: https://fantasydiscountwholesale.com/wp-content/uploads/2023/10/9113.jpeg | AC33: 1-6 | AD33: 6 | AE33: =AD33 -> 6 | AF33: 2.99 | AG33: =AF33*0.259+AF33 -> 3.76441 | AH33: =Z33*0.1-Z33 -> -3.501 | AI33: =AF33*0.4+AF33 -> 4.186 | AJ33: =1-AF33/Z33 -> 0.23136247
B34: simple | C34: 9991 | D34: SAPOLIO 930 ML . STAIN REMOVER ROPA COLOR sa-09 - 89991 | E34: 1 | F34: 0 | G34: visible | H34: SAPOLIO 930 ML . STAIN REMOVER ROPA COLOR - 89991 | I34: Sapolio Stain Remover for Colored Clothes (930ml) effectively removes tough stains while protecting fabric colors. Its powerful formula lifts dirt and grime without fading. Ideal for maintaining vibrant clothing. Perfect for wholesale and discount stores. | N34: 1 | O34: 1000 | Z34: 1.85 | AA34: cleaning supplies | AB34: https://fantasydiscountwholesale.com/wp-content/uploads/2025/02/9991.jpeg | AC34: 1-6 | AD34: 12 | AE34: =AD34 -> 12 | AF34: 1.42 | AG34: =AF34*0.25+AF34 -> 1.775 | AH34: =Z34*0.1-Z34 -> -1.665 | AI34: =AF34*0.4+AF34 -> 1.988 | AJ34: =1-AF34/Z34 -> 0.23243243
B35: simple | C35: FD083 | D35: Boli Comb Hair brush - FD083 | E35: 1 | F35: 0 | G35: visible | H35: Boli Comb Hair brush - FD083 | I35: Discover the perfect hairbrush for your daily haircare routine. Our Hair Brush is designed with your comfort and hair health in mind. Its gentle yet effective bristles effortlessly detangle and smooth your locks, reducing breakage and promoting a healthy shine. The ergonomic handle ensures a comfortable grip, making styling and brushing a breeze. Upgrade your haircare essentials and achieve the beautiful, well-groomed hair you deserve with our Hair Brush. Elevate your daily routine and enjoy a healthier, more manageable mane. Get yours today for tangle-free, gorgeous hair! 💇‍♀️✨🌟 | N35: 1 | O35: 1000 | Z35: 1.1 | AA35: Beauty & Personal Care | AB35: https://fantasydiscountwholesale.com/wp-content/uploads/2023/10/FD083-1.jpeg ,https://fantasydiscountwholesale.com/wp-content/uploads/2023/10/FD083.jpeg | AC35: 2-1 | AD35: 12 | AE35: =AD35 -> 12 | AF35: 0.5 | AG35: =AF35*0.5+AF35 -> 0.75 | AH35: =Z35*0.1-Z35 -> -0.99 | AI35: =AF35*0.4+AF35 -> 0.7 | AJ35: =1-AF35/Z35 -> 0.54545455
B36: simple | C36: JW-04 | D36: Suction cups - JW-04 | E36: 1 | F36: 0 | G36: visible | H36: Transparant, waterproof, PVC suction cup with metal hook. | I36: Can be used on any smooth surface, such as glass, a window, a wall etc. Suitable for the kitchen, the bathroom, the office as well as toy accessories. Easy to install and tear off, without any damage to the surface. There is a small hook that can be used to hang items with. | N36: 1 | O36: 1000 | Z36: 1 | AA36: Bathroom | AB36: https://fantasydiscountwholesale.com/wp-content/uploads/2023/10/JW-04-1.jpeg | AC36: 2-1 | AD36: 12 | AE36: =AD36 -> 12 | AF36: 0.44 | AG36: =AF36*0.8+AF36 -> 0.792 | AH36: =Z36*0.1-Z36 -> -0.9 | AI36: =AF36*0.4+AF36 -> 0.616 | AJ36: =1-AF36/Z36 -> 0.56
B37: simple | C37: FD913 | D37: Sink Screens Strainers 3PC STRAINNER 5CM,7CM,11CM - FD913 | E37: 1 | F37: 0 | G37: visible | H37: Sink Screens Strainers 3PC STRAINNER 5CM,7CM,11CM | I37: Offer your customers the ultimate solution in kitchen convenience with our Sink Screens Strainers 3-Piece Set. This set includes strainers in three practical sizes - 5cm, 7cm, and 11cm - to suit a variety of sink dimensions and needs. These strainers effectively prevent food particles and debris from clogging drains while allowing water to flow freely. Their versatile sizes make them perfect for kitchen sinks, bathroom basins, and utility sinks. Easy to clean and maintain, these strainers are essential for any household. Stock up on this indispensable set for a hassle-free, efficient kitchen experience. | N37: 1 | O37: 1000 | Z37: 0.75 | AA37: Kitchen | AB37: https://fantasydiscountwholesale.com/wp-content/uploads/2023/10/FD913-1.jpeg | AC37: 2-2 | AD37: 12 | AE37: =AD37 -> 12 | AF37: 0.33 | AG37: =AF37*0.83+AF37 -> 0.6039 | AH37: =Z37*0.1-Z37 -> -0.675 | AI37: =AF37*0.4+AF37 -> 0.462 | AJ37: =1-AF37/Z37 -> 0.56
B38: simple | C38: CH87337 | D38: 2PCS Prong Adapter - CH87337 | E38: 1 | F38: 0 | G38: visible | H38: 2PCS Prong Adapter - CH87337 | I38: 2PCS Prong Adapter – CH87337: Converts 2-prong outlets to 3-prong, providing grounding for added safety. Compact and easy to use. Ideal for wholesale to hardware and electrical supply retailers. | N38: 1 | O38: 1000 | Z38: 1.39 | AA38: Tools | AB38: https://fantasydiscountwholesale.com/wp-content/uploads/2025/06/CH87337.jpg | AC38: 2-2 | AD38: 6 | AE38: =AD38 -> 6 | AF38: 0.87 | AG38: =AF38*0.4+AF38 -> 1.218 | AH38: =Z38*0.1-Z38 -> -1.251 | AI38: =AF38*0.4+AF38 -> 1.218 | AJ38: =1-AF38/Z38 -> 0.37410072
B39: simple | C39: IN81752 | D39: 250CT 2PK Medium Matches - IN81752 | E39: 1 | F39: 0 | G39: visible | H39: 250CT 2PK Medium Matches - IN81752 | I39: 250CT 2PK Medium Matches – IN81752: Each pack includes two boxes of 250 wooden matches, totaling 500 matches. Designed for easy strike-on-box ignition, they're ideal for lighting candles, stoves, grills, and campfires. Perfect for wholesale to hardware, camping, and general merchandise retailers. | N39: 1 | O39: 1000 | Z39: 0.79 | AA39: Kitchen | AB39: https://fantasydiscountwholesale.com/wp-content/uploads/2025/06/IN81752.jpg | AC39: 2-2 | AD39: 12 | AE39: =AD39 -> 12 | AF39: 0.51 | AG39: =AF39*0.4+AF39 -> 0.714 | AH39: =Z39*0.1-Z39 -> -0.711 | AI39: =AF39*0.4+AF39 -> 0.714 | AJ39: =1-AF39/Z39 -> 0.35443038
B40: simple | C40: IN81751 | D40: 32CT 10PK Wooden Matches- IN81751 | E40: 1 | F40: 0 | G40: visible | H40: 32CT 10PK Wooden Matches- IN81751 | I40: 32CT 10PK Wooden Pocket Matches – IN81751: Each pack contains 10 boxes of 32 wooden matches, totaling 320 matches. Strike-on-box design ensures easy ignition. Ideal for wholesale to hardware, camping, and general merchandise retailers. | N40: 1 | O40: 1000 | Z40: 0.49 | AA40: Kitchen | AB40: https://fantasydiscountwholesale.com/wp-content/uploads/2025/06/IN81751.jpg | AC40: 2-2 | AD40: 12 | AE40: =AD40 -> 12 | AF40: 0.27 | AG40: =AF40*0.58+AF40 -> 0.4266 | AH40: =Z40*0.1-Z40 -> -0.441 | AI40: =AF40*0.4+AF40 -> 0.378 | AJ40: =1-AF40/Z40 -> 0.44897959
...

Sheet significado
A1: ID | B1: Type | C1: SKU | D1: Name | E1: Published | F1: Is featured? | G1: Visibility in catalog | H1: Short description | I1: Description | J1: Date sale price starts | K1: Date sale price ends | L1: Tax status | M1: Tax class | N1: In stock? | O1: Stock | P1: Low stock amount | Q1: Backorders allowed? | R1: Sold individually? | S1: Weight (kg) | T1: Length (cm) | U1: Width (cm) | V1: Height (cm) | W1: Allow customer reviews? | X1: Purchase note | Y1: Sale price | Z1: Regular price | AA1: Categories | AB1: Tags | AC1: Shipping class | AD1: Images | AE1: Download limit | AF1: Download expiry days | AG1: Parent | AH1: Grouped products | AI1: Upsells | AJ1: Cross-sells | AK1: External URL | AL1: Button text | AM1: Position | AN1: Product Location | AO1: Items per Products | AP1: Meta: _ic_cogs_cost | AQ1: Valor(es) del atributo 1 | AR1: Atributo visible 1 | AS1: Atributo global 1 | AT1: Nombre de la descarga 1 | AU1: URL de la descarga 1
I13: UPDATE CATALOGO: SHEETS-DOWLOAD\ WEB-PRODUCT-IMPORTS-FILE-EXISTING PRODUST

Sheet Significado-Catalogo
A1: ID | B1: Definición | C1: Tipo | D1: Definición | E1: SKU | F1: Definición | G1: Name | H1: Publicado | I1: Definición | J1: ¿Está destacado? | K1: Definición | L1: Visibilidad en el catálogo | M1: Definición | N1: Short Description | O1: Description | P1: Date sale price starts | Q1: Definición | R1: Date sale price ends | S1: Definición | T1: Tax status | U1: Tax class | V1: Definición | W1: Regular Price | X1: Categories | Y1: Images | Z1: In stock? | AA1: Definición | AB1: Stock | AC1: Items per Products | AD1: Definición | AE1: Meta: _ic_cogs_cost | AF1: Definición
A2: Identificacion del producto | B2: Numero unico e irrepetible de cada producto | C2: external | D2: productos afiliados | E2: stock keeping unit | F2: código de referencia | G2: Nombde del producto | H2: -1 | I2: borrador | J2: 0 | K2: no | L2: hidden | M2: oculto | N2: Descripcion corta del producto | O2: Descripcion completa del producto que se muestra en la pagina del producto | P2: 2021-02-24 | Q2: sin hora | R2: 2021-02-24 | S2: sin hora | T2: Taxable o se deja en blanco sino es taxable | U2: parent | V2: si es producto con variante y es igual que el padre | W2: Precio Regular | X2: Categoria del producto | Y2: Link o URL de la imagen alojada en Wordpress | Z2: 0 | AA2: Agotado | AB2: Cantidad de articulos del mismo producto | AC2: Items por products | AD2: Cantidad mínima a ser vendida por producto | AE2: Cost of Goods | AF2: Costo inicial del producto antes de la venta
C3: simple | D3: sin variantes | H3: 0 | I3: no | J3: 1 | K3: si | L3: visible | M3: visible | P3: 2021-02-24 0:00:00 | Q3: con hora | R3: 2021-02-24 0:00:00 | S3: con hora | U3: Estándar | V3: padre | Z3: 1 | AA3: Hay existencias
C4: simple, downloadable | D4: sin variantes. Los productos descargables dan acceso a un archivo después de la compra | H4: 1 | I4: si | U4: Tasa cero | V4: padre | Z4: backorder | AA4: Se puede reservar
C5: simple, downloadable, virtual | D5: sin variantes. | U5: Tasa reducida | V5: padre
C6: simple, virtual | D6: sin variantes. Los productos virtuales son intangibles y no se envían | L6: si alguien busca numero si aparece
C7: variable | D7: padre
C8: variation | D8: hijos
C9: variation, downloadable | D9: hijos
C10: variation, downloadable, virtual | D10: hijos
C11: variation, virtual | D11: hijos | I11: Processing
I12: Ready to go
I13: Deliverd
A14: Alpha insights | B14: para manage expenses | I14: Pending payment
A15: Alpha insights / p&l | B15: para ver full reports
A16: Para cargar plantilla | B16: Plantilla-file-dowload-csv / produtcs - import - choose file - continue - run importer. | K16: si hay
A17: Para cargar pagina | B17: product- export- chulo- generate / file - import - upload - browse - wc (import data) | K17: no hay
A18: Crear % (regla) de producto | B18: woocomers - pricing and discount (por cliente) \ VC aetting (general discount) | K18: No hay y no se traera
A19: Crear cupones | B19: Marketing - Coupons - add coupons | K19: falta foto
A20: para ver ventas (Analytics)
A21: cargar precio especial | B21: file- dowload-csv / csp- import-file
A23: - SIN STOCK / SALE OUT OF STOCK

Sheet DOLLAR HOUSE
A1: ='CATALOGO PAGINA'!C1 -> SKU | B1: User | C1: Min Qty | D1: Flat | E1: %
A2: ='CATALOGO PAGINA'!C2 -> FD853 | B2: DOLLAR HOUSE | C2: ='CATALOGO PAGINA'!AE2 -> 6 | D2: ='CATALOGO PAGINA'!AF2*0.13+'CATALOGO PAGINA'!AF2 -> 3.8533
A3: ='CATALOGO PAGINA'!C3 -> FD1013S | B3: DOLLAR HOUSE | C3: ='CATALOGO PAGINA'!AE3 -> 12 | D3: ='CATALOGO PAGINA'!AF3*0.13+'CATALOGO PAGINA'!AF3 -> 0.3277
A4: ='CATALOGO PAGINA'!C4 -> FD1013M | B4: DOLLAR HOUSE | C4: ='CATALOGO PAGINA'!AE4 -> 12 | D4: ='CATALOGO PAGINA'!AF4*0.13+'CATALOGO PAGINA'!AF4 -> 0.3277
A5: ='CATALOGO PAGINA'!C5 -> FD1013L | B5: DOLLAR HOUSE | C5: ='CATALOGO PAGINA'!AE5 -> 12 | D5: ='CATALOGO PAGINA'!AF5*0.13+'CATALOGO PAGINA'!AF5 -> 0.3277
A6: ='CATALOGO PAGINA'!C6 -> CN91092-A | B6: DOLLAR HOUSE | C6: ='CATALOGO PAGINA'!AE6 -> 12 | D6: ='CATALOGO PAGINA'!AF6*0.13+'CATALOGO PAGINA'!AF6 -> 1.1187
A7: ='CATALOGO PAGINA'!C7 -> 41661 | B7: DOLLAR HOUSE | C7: ='CATALOGO PAGINA'!AE7 -> 6 | D7: ='CATALOGO PAGINA'!AF7*0.13+'CATALOGO PAGINA'!AF7 -> 2.3165
A8: ='CATALOGO PAGINA'!C8 -> FD1606 | B8: DOLLAR HOUSE | C8: ='CATALOGO PAGINA'!AE8 -> 12 | D8: ='CATALOGO PAGINA'!AF8*0.13+'CATALOGO PAGINA'!AF8 -> 1.582
A9: ='CATALOGO PAGINA'!C9 -> 801440 | B9: DOLLAR HOUSE | C9: ='CATALOGO PAGINA'!AE9 -> 12 | D9: ='CATALOGO PAGINA'!AF9*0.13+'CATALOGO PAGINA'!AF9 -> 1.1074
A10: ='CATALOGO PAGINA'!C10 -> 8888 | B10: DOLLAR HOUSE | C10: ='CATALOGO PAGINA'!AE10 -> 48 | D10: ='CATALOGO PAGINA'!AF10*0.13+'CATALOGO PAGINA'!AF10 -> 0.4068
A11: ='CATALOGO PAGINA'!C11 -> 6134 | B11: DOLLAR HOUSE | C11: ='CATALOGO PAGINA'!AE11 -> 12 | D11: ='CATALOGO PAGINA'!AF11*0.13+'CATALOGO PAGINA'!AF11 -> 1.5142
A12: ='CATALOGO PAGINA'!C12 -> 8594 | B12: DOLLAR HOUSE | C12: ='CATALOGO PAGINA'!AE12 -> 12 | D12: ='CATALOGO PAGINA'!AF12*0.13+'CATALOGO PAGINA'!AF12 -> 2.0227
A13: ='CATALOGO PAGINA'!C13 -> 7532 | B13: DOLLAR HOUSE | C13: ='CATALOGO PAGINA'!AE13 -> 12 | D13: ='CATALOGO PAGINA'!AF13*0.13+'CATALOGO PAGINA'!AF13 -> 1.1752
... A1692: ='CATALOGO PAGINA'!C1692 -> 02447 | B1692: DOLLAR HOUSE | C1692: ='CATALOGO PAGINA'!AE1692 -> 12 | D1692: ='CATALOGO PAGINA'!AF1692*0.13+'CATALOGO PAGINA'!AF1692 -> 1.0848
A1693: ='CATALOGO PAGINA'!C1693
A1694: ='CATALOGO PAGINA'!C1694
A1695: ='CATALOGO PAGINA'!C1695

Sheet FANTASY DISCOUNT
A1: SKU | B1: User | C1: Min Qty | D1: Flat | E1: %
A2: ='CATALOGO PAGINA'!C2 -> FD853 | B2: FANTASY DISCOUNT | C2: ='CATALOGO PAGINA'!AE2 -> 6 | D2: ='CATALOGO PAGINA'!AF2*0.13+'CATALOGO PAGINA'!AF2 -> 3.8533
A3: ='CATALOGO PAGINA'!C3 -> FD1013S | B3: FANTASY DISCOUNT | C3: ='CATALOGO PAGINA'!AE3 -> 12 | D3: ='CATALOGO PAGINA'!AF3*0.13+'CATALOGO PAGINA'!AF3 -> 0.3277
A4: ='CATALOGO PAGINA'!C4 -> FD1013M | B4: FANTASY DISCOUNT | C4: ='CATALOGO PAGINA'!AE4 -> 12 | D4: ='CATALOGO PAGINA'!AF4*0.13+'CATALOGO PAGINA'!AF4 -> 0.3277
A5: ='CATALOGO PAGINA'!C5 -> FD1013L | B5: FANTASY DISCOUNT | C5: ='CATALOGO PAGINA'!AE5 -> 12 | D5: ='CATALOGO PAGINA'!AF5*0.13+'CATALOGO PAGINA'!AF5 -> 0.3277
A6: ='CATALOGO PAGINA'!C6 -> CN91092-A | B6: FANTASY DISCOUNT | C6: ='CATALOGO PAGINA'!AE6 -> 12 | D6: ='CATALOGO PAGINA'!AF6*0.13+'CATALOGO PAGINA'!AF6 -> 1.1187
A7: ='CATALOGO PAGINA'!C7 -> 41661 | B7: FANTASY DISCOUNT | C7: ='CATALOGO PAGINA'!AE7 -> 6 | D7: ='CATALOGO PAGINA'!AF7*0.13+'CATALOGO PAGINA'!AF7 -> 2.3165
A8: ='CATALOGO PAGINA'!C8 -> FD1606 | B8: FANTASY DISCOUNT | C8: ='CATALOGO PAGINA'!AE8 -> 12 | D8: ='CATALOGO PAGINA'!AF8*0.13+'CATALOGO PAGINA'!AF8 -> 1.582
A9: ='CATALOGO PAGINA'!C9 -> 801440 | B9: FANTASY DISCOUNT | C9: ='CATALOGO PAGINA'!AE9 -> 12 | D9: ='CATALOGO PAGINA'!AF9*0.13+'CATALOGO PAGINA'!AF9 -> 1.1074
A10: ='CATALOGO PAGINA'!C10 -> 8888 | B10: FANTASY DISCOUNT | C10: ='CATALOGO PAGINA'!AE10 -> 48 | D10: ='CATALOGO PAGINA'!AF10*0.13+'CATALOGO PAGINA'!AF10 -> 0.4068
A11: ='CATALOGO PAGINA'!C11 -> 6134 | B11: FANTASY DISCOUNT | C11: ='CATALOGO PAGINA'!AE11 -> 12 | D11: ='CATALOGO PAGINA'!AF11*0.13+'CATALOGO PAGINA'!AF11 -> 1.5142
A12: ='CATALOGO PAGINA'!C12 -> 8594 | B12: FANTASY DISCOUNT | C12: ='CATALOGO PAGINA'!AE12 -> 12 | D12: ='CATALOGO PAGINA'!AF12*0.13+'CATALOGO PAGINA'!AF12 -> 2.0227
A13: ='CATALOGO PAGINA'!C13 -> 7532 | B13: FANTASY DISCOUNT | C13: ='CATALOGO PAGINA'!AE13 -> 12 | D13: ='CATALOGO PAGINA'!AF13*0.13+'CATALOGO PAGINA'!AF13 -> 1.1752
... A1692: ='CATALOGO PAGINA'!C1692 -> 02447 | B1692: FANTASY DISCOUNT | C1692: ='CATALOGO PAGINA'!AE1692 -> 12 | D1692: ='CATALOGO PAGINA'!AF1692*0.13+'CATALOGO PAGINA'!AF1692 -> 1.0848
A1693: ='CATALOGO PAGINA'!C1693
A1694: ='CATALOGO PAGINA'!C1694
A1695: ='CATALOGO PAGINA'!C1695

Sheet attack
A1: ='CATALOGO PAGINA'!C1 -> SKU | B1: User | C1: Min Qty | D1: Flat | E1: %
A2: ='CATALOGO PAGINA'!C2 -> FD853 | B2: ATTACK | C2: ='CATALOGO PAGINA'!AE2 -> 6 | D2: ='CATALOGO PAGINA'!AG2 -> 0.99913
A3: ='CATALOGO PAGINA'!C3 -> FD1013S | B3: ATTACK | C3: ='CATALOGO PAGINA'!AE3 -> 12 | D3: ='CATALOGO PAGINA'!AG3 -> 0.754
A4: ='CATALOGO PAGINA'!C4 -> FD1013M | B4: ATTACK | C4: ='CATALOGO PAGINA'!AE4 -> 12 | D4: ='CATALOGO PAGINA'!AG4 -> 1.247
A5: ='CATALOGO PAGINA'!C5 -> FD1013L | B5: ATTACK | C5: ='CATALOGO PAGINA'!AE5 -> 12 | D5: ='CATALOGO PAGINA'!AG5 -> 1.7458
A6: ='CATALOGO PAGINA'!C6 -> CN91092-A | B6: ATTACK | C6: ='CATALOGO PAGINA'!AE6 -> 12 | D6: ='CATALOGO PAGINA'!AG6 -> 1.386
A7: ='CATALOGO PAGINA'!C7 -> 41661 | B7: ATTACK | C7: ='CATALOGO PAGINA'!AE7 -> 6 | D7: ='CATALOGO PAGINA'!AG7 -> 2.87
A8: ='CATALOGO PAGINA'!C8 -> FD1606 | B8: ATTACK | C8: ='CATALOGO PAGINA'!AE8 -> 12 | D8: ='CATALOGO PAGINA'!AG8 -> 2.8
A9: ='CATALOGO PAGINA'!C9 -> 801440 | B9: ATTACK | C9: ='CATALOGO PAGINA'!AE9 -> 12 | D9: ='CATALOGO PAGINA'!AG9 -> 1.372
A10: ='CATALOGO PAGINA'!C10 -> 8888 | B10: ATTACK | C10: ='CATALOGO PAGINA'!AE10 -> 48 | D10: ='CATALOGO PAGINA'!AG10 -> 0.468
A11: ='CATALOGO PAGINA'!C11 -> 6134 | B11: ATTACK | C11: ='CATALOGO PAGINA'!AE11 -> 12 | D11: ='CATALOGO PAGINA'!AG11 -> 1.675
A12: ='CATALOGO PAGINA'!C12 -> 8594 | B12: ATTACK | C12: ='CATALOGO PAGINA'!AE12 -> 12 | D12: ='CATALOGO PAGINA'!AG12 -> 2.2375
A13: ='CATALOGO PAGINA'!C13 -> 7532 | B13: ATTACK | C13: ='CATALOGO PAGINA'!AE13 -> 12 | D13: ='CATALOGO PAGINA'!AG13 -> 1.3
... A1692: ='CATALOGO PAGINA'!C1692 -> 02447 | B1692: ATTACK | C1692: ='CATALOGO PAGINA'!AE1692 -> 12 | D1692: ='CATALOGO PAGINA'!AG1692 -> 1.2864
A1693: ='CATALOGO PAGINA'!C1693
A1694: ='CATALOGO PAGINA'!C1694
A1695: ='CATALOGO PAGINA'!C1695

Sheet next level
A1: SKU | B1: User | C1: Min Qty | D1: Flat | E1: %
A2: ='CATALOGO PAGINA'!C2 -> FD853 | B2: Next level | C2: ='CATALOGO PAGINA'!AE2 -> 6 | D2: ='CATALOGO PAGINA'!AG2 -> 0.99913
A3: ='CATALOGO PAGINA'!C3 -> FD1013S | B3: Next level | C3: ='CATALOGO PAGINA'!AE3 -> 12 | D3: ='CATALOGO PAGINA'!AG3 -> 0.754
A4: ='CATALOGO PAGINA'!C4 -> FD1013M | B4: Next level | C4: ='CATALOGO PAGINA'!AE4 -> 12 | D4: ='CATALOGO PAGINA'!AG4 -> 1.247
A5: ='CATALOGO PAGINA'!C5 -> FD1013L | B5: Next level | C5: ='CATALOGO PAGINA'!AE5 -> 12 | D5: ='CATALOGO PAGINA'!AG5 -> 1.7458
A6: ='CATALOGO PAGINA'!C6 -> CN91092-A | B6: Next level | C6: ='CATALOGO PAGINA'!AE6 -> 12 | D6: ='CATALOGO PAGINA'!AG6 -> 1.386
A7: ='CATALOGO PAGINA'!C7 -> 41661 | B7: Next level | C7: ='CATALOGO PAGINA'!AE7 -> 6 | D7: ='CATALOGO PAGINA'!AG7 -> 2.87
A8: ='CATALOGO PAGINA'!C8 -> FD1606 | B8: Next level | C8: ='CATALOGO PAGINA'!AE8 -> 12 | D8: ='CATALOGO PAGINA'!AG8 -> 2.8
A9: ='CATALOGO PAGINA'!C9 -> 801440 | B9: Next level | C9: ='CATALOGO PAGINA'!AE9 -> 12 | D9: ='CATALOGO PAGINA'!AG9 -> 1.372
A10: ='CATALOGO PAGINA'!C10 -> 8888 | B10: Next level | C10: ='CATALOGO PAGINA'!AE10 -> 48 | D10: ='CATALOGO PAGINA'!AG10 -> 0.468
A11: ='CATALOGO PAGINA'!C11 -> 6134 | B11: Next level | C11: ='CATALOGO PAGINA'!AE11 -> 12 | D11: ='CATALOGO PAGINA'!AG11 -> 1.675
A12: ='CATALOGO PAGINA'!C12 -> 8594 | B12: Next level | C12: ='CATALOGO PAGINA'!AE12 -> 12 | D12: ='CATALOGO PAGINA'!AG12 -> 2.2375
A13: ='CATALOGO PAGINA'!C13 -> 7532 | B13: Next level | C13: ='CATALOGO PAGINA'!AE13 -> 12 | D13: ='CATALOGO PAGINA'!AG13 -> 1.3
... A1634: ='CATALOGO PAGINA'!C1634 -> 1977R | B1634: Next level | C1634: ='CATALOGO PAGINA'!AE1634 -> 12 | D1634: ='CATALOGO PAGINA'!AG1634 -> 0.686
A1635: ='CATALOGO PAGINA'!C1634 -> 1977R | B1635: Next level | C1635: ='CATALOGO PAGINA'!AE1635 -> 12 | D1635: ='CATALOGO PAGINA'!AG1635 -> 0.7473
A1636: ='CATALOGO PAGINA'!C1635 -> 1417R | B1636: Next level | C1636: ='CATALOGO PAGINA'!AE1636 -> 12 | D1636: ='CATALOGO PAGINA'!AG1636 -> 0.7473
A1637: ='CATALOGO PAGINA'!C1636 -> 1418R | B1637: Next level | C1637: ='CATALOGO PAGINA'!AE1637 -> 12 | D1637: ='CATALOGO PAGINA'!AG1637 -> 0.6909
A1638: ='CATALOGO PAGINA'!C1637 -> 0289IV | B1638: Next level | C1638: ='CATALOGO PAGINA'!AE1638 -> 12 | D1638: ='CATALOGO PAGINA'!AG1638 -> 0.6909
A1639: ='CATALOGO PAGINA'!C1638 -> 0002E5 | B1639: Next level | C1639: ='CATALOGO PAGINA'!AE1639 -> 12 | D1639: ='CATALOGO PAGINA'!AG1639 -> 0.6909
A1640: ='CATALOGO PAGINA'!C1639 -> 0537R12 | B1640: Next level | C1640: ='CATALOGO PAGINA'!AE1640 -> 12 | D1640: ='CATALOGO PAGINA'!AG1640 -> 0.6909
A1641: ='CATALOGO PAGINA'!C1640 -> 0290IV | B1641: Next level | C1641: ='CATALOGO PAGINA'!AE1641 -> 12 | D1641: ='CATALOGO PAGINA'!AG1641 -> 0.6909
A1642: ='CATALOGO PAGINA'!C1641 -> 0803R6 | B1642: Next level | C1642: ='CATALOGO PAGINA'!AE1642 -> 12 | D1642: ='CATALOGO PAGINA'!AG1642 -> 0.6909
A1643: ='CATALOGO PAGINA'!C1642 -> 0708R12 | B1643: Next level | C1643: ='CATALOGO PAGINA'!AE1643 -> 6 | D1643: ='CATALOGO PAGINA'!AG1643 -> 0.7473
A1644: ='CATALOGO PAGINA'!C1643 -> HM65082 | B1644: Next level | C1644: ='CATALOGO PAGINA'!AE1644 -> 6 | D1644: ='CATALOGO PAGINA'!AG1644 -> 1.05
A1645: ='CATALOGO PAGINA'!C1644 -> 378537 | B1645: Next level | C1645: ='CATALOGO PAGINA'!AE1645 -> 12 | D1645: ='CATALOGO PAGINA'!AG1645 -> 3.04885
A1646: ='CATALOGO PAGINA'!C1645 -> 6570 | B1646: Next level | C1646: ='CATALOGO PAGINA'!AE1646 -> 12 | D1646: ='CATALOGO PAGINA'!AG1646 -> 3.04885
... A1692: ='CATALOGO PAGINA'!C1691 -> 02445 | B1692: Next level | C1692: ='CATALOGO PAGINA'!AE1692 -> 12 | D1692: ='CATALOGO PAGINA'!AG1692 -> 1.2864
A1693: ='CATALOGO PAGINA'!C1692 -> 02447 | B1693: Next level | C1693: ='CATALOGO PAGINA'!AE1693
A1694: ='CATALOGO PAGINA'!C1693
A1695: ='CATALOGO PAGINA'!C1694

Sheet GOVERNMENT
A1: SKU | B1: User | C1: Min Qty | D1: Flat | E1: %
A2: ='CATALOGO PAGINA'!C2 -> FD853 | B2: GOVERNMENT | C2: ='CATALOGO PAGINA'!AE2 -> 6 | D2: ='CATALOGO PAGINA'!AG2 -> 0.99913
A3: ='CATALOGO PAGINA'!C3 -> FD1013S | B3: GOVERNMENT | C3: ='CATALOGO PAGINA'!AE3 -> 12 | D3: ='CATALOGO PAGINA'!AG3 -> 0.754
A4: ='CATALOGO PAGINA'!C4 -> FD1013M | B4: GOVERNMENT | C4: ='CATALOGO PAGINA'!AE4 -> 12 | D4: ='CATALOGO PAGINA'!AG4 -> 1.247
A5: ='CATALOGO PAGINA'!C5 -> FD1013L | B5: GOVERNMENT | C5: ='CATALOGO PAGINA'!AE5 -> 12 | D5: ='CATALOGO PAGINA'!AG5 -> 1.7458
A6: ='CATALOGO PAGINA'!C6 -> CN91092-A | B6: GOVERNMENT | C6: ='CATALOGO PAGINA'!AE6 -> 12 | D6: ='CATALOGO PAGINA'!AG6 -> 1.386
A7: ='CATALOGO PAGINA'!C7 -> 41661 | B7: GOVERNMENT | C7: ='CATALOGO PAGINA'!AE7 -> 6 | D7: ='CATALOGO PAGINA'!AG7 -> 2.87
A8: ='CATALOGO PAGINA'!C8 -> FD1606 | B8: GOVERNMENT | C8: ='CATALOGO PAGINA'!AE8 -> 12 | D8: ='CATALOGO PAGINA'!AG8 -> 2.8
A9: ='CATALOGO PAGINA'!C9 -> 801440 | B9: GOVERNMENT | C9: ='CATALOGO PAGINA'!AE9 -> 12 | D9: ='CATALOGO PAGINA'!AG9 -> 1.372
A10: ='CATALOGO PAGINA'!C10 -> 8888 | B10: GOVERNMENT | C10: ='CATALOGO PAGINA'!AE10 -> 48 | D10: ='CATALOGO PAGINA'!AG10 -> 0.468
A11: ='CATALOGO PAGINA'!C11 -> 6134 | B11: GOVERNMENT | C11: ='CATALOGO PAGINA'!AE11 -> 12 | D11: ='CATALOGO PAGINA'!AG11 -> 1.675
A12: ='CATALOGO PAGINA'!C12 -> 8594 | B12: GOVERNMENT | C12: ='CATALOGO PAGINA'!AE12 -> 12 | D12: ='CATALOGO PAGINA'!AG12 -> 2.2375
A13: ='CATALOGO PAGINA'!C13 -> 7532 | B13: GOVERNMENT | C13: ='CATALOGO PAGINA'!AE13 -> 12 | D13: ='CATALOGO PAGINA'!AG13 -> 1.3
... A1692: ='CATALOGO PAGINA'!C1692 -> 02447 | B1692: GOVERNMENT | C1692: ='CATALOGO PAGINA'!AE1692 -> 12 | D1692: ='CATALOGO PAGINA'!AG1692 -> 1.2864
A1693: ='CATALOGO PAGINA'!C1693
A1694: ='CATALOGO PAGINA'!C1694
A1695: ='CATALOGO PAGINA'!C1695

Sheet Ramdelsa
A1: SKU | B1: User | C1: Min Qty | D1: Flat | E1: %
A2: ='CATALOGO PAGINA'!C2 -> FD853 | B2: Ramdelsa | C2: ='CATALOGO PAGINA'!AE2 -> 6 | D2: ='CATALOGO PAGINA'!AG2 -> 0.99913
A3: ='CATALOGO PAGINA'!C3 -> FD1013S | B3: Ramdelsa | C3: ='CATALOGO PAGINA'!AE3 -> 12 | D3: ='CATALOGO PAGINA'!AG3 -> 0.754
A4: ='CATALOGO PAGINA'!C4 -> FD1013M | B4: Ramdelsa | C4: ='CATALOGO PAGINA'!AE4 -> 12 | D4: ='CATALOGO PAGINA'!AG4 -> 1.247
A5: ='CATALOGO PAGINA'!C5 -> FD1013L | B5: Ramdelsa | C5: ='CATALOGO PAGINA'!AE5 -> 12 | D5: ='CATALOGO PAGINA'!AG5 -> 1.7458
A6: ='CATALOGO PAGINA'!C6 -> CN91092-A | B6: Ramdelsa | C6: ='CATALOGO PAGINA'!AE6 -> 12 | D6: ='CATALOGO PAGINA'!AG6 -> 1.386
A7: ='CATALOGO PAGINA'!C7 -> 41661 | B7: Ramdelsa | C7: ='CATALOGO PAGINA'!AE7 -> 6 | D7: ='CATALOGO PAGINA'!AG7 -> 2.87
A8: ='CATALOGO PAGINA'!C8 -> FD1606 | B8: Ramdelsa | C8: ='CATALOGO PAGINA'!AE8 -> 12 | D8: ='CATALOGO PAGINA'!AG8 -> 2.8
A9: ='CATALOGO PAGINA'!C9 -> 801440 | B9: Ramdelsa | C9: ='CATALOGO PAGINA'!AE9 -> 12 | D9: ='CATALOGO PAGINA'!AG9 -> 1.372
A10: ='CATALOGO PAGINA'!C10 -> 8888 | B10: Ramdelsa | C10: ='CATALOGO PAGINA'!AE10 -> 48 | D10: ='CATALOGO PAGINA'!AG10 -> 0.468
A11: ='CATALOGO PAGINA'!C11 -> 6134 | B11: Ramdelsa | C11: ='CATALOGO PAGINA'!AE11 -> 12 | D11: ='CATALOGO PAGINA'!AG11 -> 1.675
A12: ='CATALOGO PAGINA'!C12 -> 8594 | B12: Ramdelsa | C12: ='CATALOGO PAGINA'!AE12 -> 12 | D12: ='CATALOGO PAGINA'!AG12 -> 2.2375
A13: ='CATALOGO PAGINA'!C13 -> 7532 | B13: Ramdelsa | C13: ='CATALOGO PAGINA'!AE13 -> 12 | D13: ='CATALOGO PAGINA'!AG13 -> 1.3
... A1692: ='CATALOGO PAGINA'!C1692 -> 02447 | B1692: Ramdelsa | C1692: ='CATALOGO PAGINA'!AE1692 -> 12 | D1692: ='CATALOGO PAGINA'!AG1692 -> 1.2864
A1693: ='CATALOGO PAGINA'!C1693
A1694: ='CATALOGO PAGINA'!C1694
A1695: ='CATALOGO PAGINA'!C1695
A1696: ='CATALOGO PAGINA'!C1696

Sheet Valores
A1: Tipo | B1: Definición | C1: Publicado | D1: Definición | E1: ¿Está destacado? | F1: Definición | G1: Visibilidad en el catálogo | H1: Definición | I1: Fecha de inicio/fin del precio rebajado | J1: Definición | K1: Estado del impuesto | L1: Clase del impuesto | M1: Definición | N1: ¿En inventario? | O1: Definición | P1: ¿Permitir reservar productos agotados? | Q1: ¿Vendido individualmente? | R1: ¿Permitir valoraciones de clientes? | S1: Definición | T1: Atributo visible 1 | U1: Definición | V1: Atributo global 1 | W1: Definición
A2: external | B2: productos afiliados | C2: -1 | D2: borrador | E2: 0 | F2: no | G2: hidden | H2: oculto | I2: 2021-02-24 | J2: sin hora | K2: taxable | L2: parent | M2: si es producto con variante y es igual que el padre | N2: 0 | O2: Agotado | P2: 0 | Q2: 0 | R2: 0 | S2: padre | T2: 0 | U2: No | V2: 0 | W2: No
A3: simple | B3: sin variantes | C3: 0 | D3: no | E3: 1 | F3: si | G3: visible | H3: visible | I3: 2021-02-24 0:00:00 | J3: con hora | L3: Estándar | M3: padre | N3: 1 | O3: Hay existencias | P3: 1 | Q3: 1 | R3: 1 | S3: hijos | T3: 1 | U3: Sí | V3: 1 | W3: Sí
A4: simple, downloadable | B4: sin variantes. Los productos descargables dan acceso a un archivo después de la compra | C4: 1 | D4: si | L4: Tasa cero | M4: padre | N4: backorder | O4: Se puede reservar | Q4: 12
A5: simple, downloadable, virtual | B5: sin variantes. | L5: Tasa reducida | M5: padre
A6: simple, virtual | B6: sin variantes. Los productos virtuales son intangibles y no se envían
A7: variable | B7: padre
A8: variation | B8: hijos
A9: variation, downloadable | B9: hijos
A10: variation, downloadable, virtual | B10: hijos
A11: variation, virtual | B11: hijos
